2021-08-12 21:27:41,387 ERROR Internal Server Error: /posts/ /home/river/NewsBlog/venv/lib/python3.9/site-packages/django/utils/log.py (<class 'AttributeError'>, AttributeError("'super' object has no attribute 'gt_context_data'"), <traceback object at 0x7f018e5b7800>)
Traceback (most recent call last):
  File "/home/river/NewsBlog/venv/lib/python3.9/site-packages/django/core/handlers/exception.py", line 47, in inner
    response = get_response(request)
  File "/home/river/NewsBlog/venv/lib/python3.9/site-packages/django/core/handlers/base.py", line 181, in _get_response
    response = wrapped_callback(request, *callback_args, **callback_kwargs)
  File "/home/river/NewsBlog/venv/lib/python3.9/site-packages/django/utils/decorators.py", line 130, in _wrapped_view
    response = view_func(request, *args, **kwargs)
  File "/home/river/NewsBlog/venv/lib/python3.9/site-packages/django/views/generic/base.py", line 70, in view
    return self.dispatch(request, *args, **kwargs)
  File "/home/river/NewsBlog/venv/lib/python3.9/site-packages/django/views/generic/base.py", line 98, in dispatch
    return handler(request, *args, **kwargs)
  File "/home/river/NewsBlog/venv/lib/python3.9/site-packages/django/views/generic/list.py", line 157, in get
    context = self.get_context_data()
  File "/home/river/NewsBlog/news/views.py", line 25, in get_context_data
    context = {**super().gt_context_data(*args, **kwargs),
AttributeError: 'super' object has no attribute 'gt_context_data'
2021-08-12 21:27:41,992 ERROR "GET /posts/ HTTP/1.1" 500 145 /home/river/NewsBlog/venv/lib/python3.9/site-packages/django/core/servers/basehttp.py None
